<?xml version="1.0"?>

<robot xmlns:xacro="http://www.ros.org/wiki/xacro">

  <link name="gripper_base">
    <collision>
      <origin rpy="0 0 0" xyz="0 0 0.0065"/>
      <geometry>
        <box size="0.02 0.01 0.002"/>
      </geometry>
    </collision>
    <visual>
      <origin rpy="0 0 0" xyz="0 0 0.0065"/>
      <geometry>
        <box size="0.02 0.01 0.002"/>
      </geometry>
      <material name="gray">
        <color rgba="1 1 1 0.5"/>
      </material>
    </visual>
    <inertial>
      <origin rpy="0 0 0" xyz="0 0 0"/>
      <mass value="0.2"/>
      <inertia ixx="0.00000173" ixy="0.0" ixz="0.0" 
               iyy="0.00000673" iyz="0.0" 
               izz="0.00000833"/>
    </inertial>
  </link>

  <link name="finger1">
    <collision>
      <origin rpy="0 0 0" xyz="0.01 0 0.014"/>
      <geometry>
        <box size="0.002 0.01 0.015"/>
      </geometry>
    </collision>
    <visual>
      <origin rpy="0 0 0" xyz="0.01 0 0.014"/>
      <geometry>
        <box size="0.002 0.01 0.015"/>
      </geometry>
      <material name="gray">
        <color rgba="1 1 1 0.5"/>
      </material>
    </visual>
    <inertial>
      <origin rpy="0 0 0" xyz="0 0 0"/>
      <mass value="0.1"/>
      <inertia ixx="0.0000027" ixy="0.0" ixz="0.0" 
               iyy="0.000001908" iyz="0.0" 
               izz="0.00000086"/>
    </inertial>
  </link>

  <link name="finger2">
    <collision>
      <origin rpy="0 0 0" xyz="-0.01 0 0.014"/>
      <geometry>
        <box size="0.002 0.01 0.015"/>
      </geometry>
    </collision>
    <visual>
      <origin rpy="0 0 0" xyz="-0.01 0 0.014"/>
      <geometry>
        <box size="0.002 0.01 0.015"/>
      </geometry>
      <material name="gray">
        <color rgba="1 1 1 0.5"/>
      </material>
    </visual>
    <inertial>
      <origin rpy="0 0 0" xyz="0 0 0"/>
      <mass value="0.1"/>
      <inertia ixx="0.0000027" ixy="0.0" ixz="0.0" 
               iyy="0.000001908" iyz="0.0" 
               izz="0.00000086"/>
    </inertial>
  </link>


  <joint name="joint6" type="prismatic">
    <parent link="gripper_base"/>
    <child link="finger1"/>
    <limit effort="10000.0" lower="0.0" upper="0.008" velocity="100.0"/>
    <origin rpy="0 0 0" xyz="0 0 0"/>
    <axis xyz="-1 0 0" />
  </joint>

  <joint name="joint7" type="prismatic">
    <parent link="gripper_base"/>
    <child link="finger2"/>
    <limit effort="10000.0" lower="0.0" upper="0.008" velocity="100.0"/>
    <origin rpy="0 0 0" xyz="0 0 0"/>
    <axis xyz="1 0 0" />
  </joint>


</robot>